[2020-06-08 19:44:31,618] {taskinstance.py:669} INFO - Dependencies all met for <TaskInstance: my_dag.source1 2020-06-08T14:13:36.673104+00:00 [queued]>
[2020-06-08 19:44:31,629] {taskinstance.py:669} INFO - Dependencies all met for <TaskInstance: my_dag.source1 2020-06-08T14:13:36.673104+00:00 [queued]>
[2020-06-08 19:44:31,629] {taskinstance.py:879} INFO - 
--------------------------------------------------------------------------------
[2020-06-08 19:44:31,629] {taskinstance.py:880} INFO - Starting attempt 1 of 2
[2020-06-08 19:44:31,630] {taskinstance.py:881} INFO - 
--------------------------------------------------------------------------------
[2020-06-08 19:44:31,650] {taskinstance.py:900} INFO - Executing <Task(PythonOperator): source1> on 2020-06-08T14:13:36.673104+00:00
[2020-06-08 19:44:31,652] {standard_task_runner.py:53} INFO - Started process 13982 to run task
[2020-06-08 19:44:31,727] {logging_mixin.py:112} INFO - Running %s on host %s <TaskInstance: my_dag.source1 2020-06-08T14:13:36.673104+00:00 [running]> nineleaps-ThinkPad-E470
[2020-06-08 19:44:31,737] {taskinstance.py:1145} ERROR - fetch_covid_data() takes no arguments (37 given)
Traceback (most recent call last):
  File "/home/nineleaps/.local/lib/python2.7/site-packages/airflow/models/taskinstance.py", line 983, in _run_raw_task
    result = task_copy.execute(context=context)
  File "/home/nineleaps/.local/lib/python2.7/site-packages/airflow/operators/python_operator.py", line 113, in execute
    return_value = self.execute_callable()
  File "/home/nineleaps/.local/lib/python2.7/site-packages/airflow/operators/python_operator.py", line 118, in execute_callable
    return self.python_callable(*self.op_args, **self.op_kwargs)
TypeError: fetch_covid_data() takes no arguments (37 given)
[2020-06-08 19:44:31,738] {taskinstance.py:1168} INFO - Marking task as UP_FOR_RETRY
[2020-06-08 19:44:41,605] {logging_mixin.py:112} INFO - [2020-06-08 19:44:41,604] {local_task_job.py:103} INFO - Task exited with return code 1
